<?xml version="1.0"?>

<robot name="mogi_arm" xmlns:xacro="http://www.ros.org/wiki/xacro">

  <!-- RViz colors -->
  <xacro:include filename="$(find bme_ros_simple_arm)/urdf/materials.xacro" />

  <!-- Global reference link -->
  <link name="world"/>

  <joint name="fixed_base" type="fixed">
    <parent link="world"/>
    <child link="base_link"/>
  </joint>

  <!-- Arm base link -->
  <link name="base_link">
    <inertial>
      <mass value="2"/>
      <origin xyz="0.0 0.0 0.0"/>
      <inertia ixx="0.0117" ixy="0.0" ixz="0.0" 
               iyy="0.0117" iyz="0.0"
               izz="0.0225"
      />
    </inertial>
    <collision>
      <geometry>
        <cylinder radius="0.15" length="0.05"/>
      </geometry>
      <origin xyz="0.0 0.0 0.0" rpy="0.0 0.0 0.0"/>
    </collision>
    <visual>
      <geometry>
        <!--<cylinder radius="0.15" length="0.05"/>-->
        <mesh filename = "package://bme_ros_simple_arm/meshes/link0.dae"/>
      </geometry>
      <material name="grey"/>
      <origin xyz="0.0 0.0 0.0" rpy="0.0 0.0 0.0"/>
    </visual>
  </link>

  <gazebo reference="base_link">
    <material>Gazebo/Grey</material>
  </gazebo>

    <!-- Shoulder pan joint -->
  <joint name="shoulder_pan_joint" type="revolute">
    <limit lower="-3.14" upper="3.14" effort="330.0" velocity="3.14"/>
    <parent link="base_link"/>
    <child link="shoulder_link"/>
    <axis xyz="0 0 1"/>
    <origin xyz="0.0 0.0 0.05" rpy="0.0 0.0 0.0"/>
    <dynamics damping="0.0" friction="0.0"/>
  </joint>

  <!-- Shoulder link -->
  <link name="shoulder_link">
    <inertial>
      <mass value="0.5"/>
      <origin xyz="0.0 0.0 0.0" rpy="0.0 0.0 0.0"/>
      <inertia ixx="0.0014" ixy="0.0" ixz="0.0"
               iyy="0.0014" iyz="0.0"
               izz="0.0025"
      />
    </inertial>
    <collision>
      <geometry>
        <cylinder radius="0.1" length="0.05"/>
      </geometry>
      <origin xyz="0.0 0.0 0.0" rpy="0.0 0.0 0.0"/>
    </collision>
    <visual>
      <geometry>
        <cylinder radius="0.1" length="0.05"/>
      </geometry>
      <material name="orange"/>
      <origin xyz="0.0 0.0 0.0" rpy="0.0 0.0 0.0"/>
    </visual>
  </link>

  <gazebo reference="shoulder_link">
    <material>Gazebo/Orange</material>
  </gazebo>

  <!-- Shoulder lift joint -->
  <joint name="shoulder_lift_joint" type="revolute">
    <limit lower="-1.5708" upper="1.5708" effort="330.0" velocity="3.14"/>
    <parent link="shoulder_link"/>
    <child link="upper_arm_link"/>
    <axis xyz="0 1 0"/>
    <origin xyz="0.0 0.0 0.025" rpy="0.0 0.0 0.0"/>
    <dynamics damping="0.0" friction="0.0"/>
  </joint>

  <!-- Upper arm link -->
  <link name="upper_arm_link">
    <inertial>
      <mass value="0.3"/>
      <origin xyz="0.0 0.0 0.1" rpy="0.0 0.0 0.0"/>
      <inertia ixx="0.0012" ixy="0.0" ixz="0.0"
               iyy="0.0012" iyz="0.0"
               izz="0.0004"
      />
    </inertial>
    <collision>
      <geometry>
        <cylinder radius="0.05" length="0.2"/>
      </geometry>
      <origin xyz="0.0 0.0 0.1" rpy="0.0 0.0 0.0"/>
    </collision>
    <visual>
      <geometry>
        <cylinder radius="0.05" length="0.2"/>
      </geometry>
      <material name="orange"/>
      <origin xyz="0.0 0.0 0.1" rpy="0.0 0.0 0.0"/>
    </visual>
  </link>

  <gazebo reference="upper_arm_link">
    <material>Gazebo/Orange</material>
  </gazebo>

  <!-- Elbow joint -->
  <joint name="elbow_joint" type="revolute">
    <limit lower="-2.3562" upper="2.3562" effort="150.0" velocity="3.14"/>
    <parent link="upper_arm_link"/>
    <child link="forearm_link"/>
    <axis xyz="0 1 0"/>
    <origin xyz="0.0 0.0 0.2" rpy="0.0 0.0 0.0"/>
    <dynamics damping="0.0" friction="0.0"/>
  </joint>

  <!-- Forearm link -->
  <link name="forearm_link">
    <inertial>
      <mass value="0.2"/>
      <origin xyz="0.0 0.0 0.125" rpy="0.0 0.0 0.0"/>
      <inertia ixx="0.0011" ixy="0.0" ixz="0.0"
               iyy="0.0011" iyz="0.0"
               izz="0.0004"
      />
    </inertial>
    <collision>
      <geometry>
        <cylinder radius="0.025" length="0.25"/>
      </geometry>
      <origin xyz="0.0 0.0 0.125" rpy="0.0 0.0 0.0"/>
    </collision>
    <visual>
      <geometry>
        <cylinder radius="0.025" length="0.25"/>
      </geometry>
      <material name="orange"/>
      <origin xyz="0.0 0.0 0.125" rpy="0.0 0.0 0.0"/>
    </visual>
  </link>

  <gazebo reference="forearm_link">
    <material>Gazebo/Orange</material>
  </gazebo>


</robot>